Workbook

Sheet Reporte de ejecución - Entrega2
A1: GhostMan - Entrega 2 - Reporte de ejecución de casos de prueba (V2, ciclo 2)
A2: Todos los casos de prueba ordenados por ID: los nuevos de la V2, la regresión completa de la V1 (35 casos de prioridad Alta, mutados, y 29 de prioridad Media y Baja, ejecutados el 28/10/2026) y las pruebas de confirmación de defectos. Estados según la sección 12.2: Aprobado, Fallido, Bloqueado, No ejecutado, No aplica. «Estado Entrega 1» viene del reporte de la Entrega 1; «¿Cambió?» compara los dos ciclos. El ID de cada caso abre su hoja de detalle.
A3: Test case ID | B3: Tipo de prueba | C3: Épica | D3: Prioridad | E3: Título | F3: Historia de usuario | G3: Camino feliz | H3: Estado Entrega 1 | I3: Estado Entrega 2 | J3: ¿Cambió? | K3: Ejecutor | L3: Fecha | M3: Defectos | N3: Observaciones | P3: Identificación del ciclo (sección 12.1)
A4: CP-001 | B4: Regresión (V1, mutado) | C4: E1 | D4: Alta | E4: Movimiento de Pacman con las flechas | F4: HU-01 | G4: Sí | H4: Aprobado | I4: Aprobado | J4: =IF(OR(H4="—",I4="",I4="No ejecutado"),"—",IF(H4=I4,"No","Sí")) | K4: Luzzi | L4: 46307 | N4: Mutación: Secuencia invertida: ↓ → ↑ ← (la V1 usó ← ↑ → ↓). Desde el cruce (4,6), ↓ → ↑ ← desplazaron a Pacman hacia abajo, derecha, arriba e izquierda respectivamente. (Fantasmas retirados y posiciones preparadas por script para aislar la condición.) | P4: Ciclo de ejecución | Q4: Nº 2 (primer ciclo de la V2)
A5: CP-002 | B5: Regresión (V1, mutado) | C5: E1 | D5: Alta | E5: Movimiento de Pacman con WASD | F5: HU-01 | G5: Sí | H5: Aprobado | I5: Aprobado | J5: =IF(OR(H5="—",I5="",I5="No ejecutado"),"—",IF(H5=I5,"No","Sí")) | K5: Luzzi | L5: 46307 | N5: Mutación: Secuencia invertida: S D W A. S D W A produjeron el mismo desplazamiento que ↓ → ↑ ← (abajo, derecha, arriba, izquierda). (Fantasmas retirados y posiciones preparadas por script para aislar la condición.) | P5: Versión bajo prueba | Q5: V2
A6: CP-003 | B6: Regresión (V1, mutado) | C6: E1 | D6: Alta | E6: Avance continuo sin mantener la tecla | F6: HU-01 | G6: Sí | H6: Aprobado | I6: Aprobado | J6: =IF(OR(H6="—",I6="",I6="No ejecutado"),"—",IF(H6=I6,"No","Sí")) | K6: Luzzi | L6: 46307 | N6: Mutación: Se usa la dirección ↓ desde una celda distinta a la de la V1 (fila 10). Tras un toque de ↓ en (10,6), Pacman siguió bajando sin mantener la tecla hasta el muro inferior (fila 13) y se detuvo ahí. (Fantasmas retirados y posiciones preparadas por script para aislar la condición.) | P6: Commit | Q6: 7ec70df (Corregir DEF-001, rama main)
A7: CP-004 | B7: Regresión (V1, Media/Baja) | C7: E1 | D7: Media | E7: Giro postergado hasta la primera celda posible | F7: HU-01 | G7: No | H7: Aprobado | I7: Aprobado | J7: =IF(OR(H7="—",I7="",I7="No ejecutado"),"—",IF(H7=I7,"No","Sí")) | K7: Luzzi | L7: 46323 | N7: Avanzando a la derecha por la fila 4 desde (4,3), ↑ presionado 3 celdas antes de la intersección: Pacman siguió en horizontal sin detenerse y giró hacia arriba al llegar a la columna 6. (Fantasmas retirados y posiciones preparadas por script para aislar la condición.) | P7: Entorno | Q7: Build de producción local del commit 7ec70df (next build + next start), con una línea agregada solo para la prueba que expone el estado del juego al script (window.__gm, no se commitea) y sin la fuente de Google. Completar la URL de Vercel cuando se despliegue y repetir una muestra de casos ahí.
A8: CP-005 | B8: Regresión (V1, mutado) | C8: E1 | D8: Alta | E8: Dirección bloqueada por un muro | F8: HU-01 | G8: No | H8: Aprobado | I8: Aprobado | J8: =IF(OR(H8="—",I8="",I8="No ejecutado"),"—",IF(H8=I8,"No","Sí")) | K8: Luzzi | L8: 46307 | N8: Mutación: Se ejecuta en la fila 10 con ↓ bloqueado, en lugar de ↑. Avanzando a la derecha por la fila 10 con muro debajo (11,2), ↓ no lo detuvo: siguió hacia la derecha (posición 2.68). (Fantasmas retirados y posiciones preparadas por script para aislar la condición.) | P8: Navegador y versión | Q8: Chromium 141 (Playwright), sin interfaz, ventana de 560 × 600
A9: CP-006 | B9: Regresión (V1, Media/Baja) | C9: E1 | D9: Media | E9: Inversión de marcha a mitad de corredor | F9: HU-01 | G9: No | H9: Aprobado | I9: Aprobado | J9: =IF(OR(H9="—",I9="",I9="No ejecutado"),"—",IF(H9=I9,"No","Sí")) | K9: Luzzi | L9: 46323 | N9: A mitad del corredor de la fila 7 (posición 3.33, sin intersección), ← invirtió la marcha de inmediato: dirección «left», posición 3.33 → 1.92. (Fantasmas retirados y posiciones preparadas por script para aislar la condición.) | P9: Fecha de inicio | Q9: 46307
A10: CP-007 | B10: Regresión (V1, mutado) | C10: E1 | D10: Alta | E10: Pacman no atraviesa los muros | F10: HU-02 | G10: No | H10: Aprobado | I10: Aprobado | J10: =IF(OR(H10="—",I10="",I10="No ejecutado"),"—",IF(H10=I10,"No","Sí")) | K10: Luzzi | L10: 46307 | N10: Mutación: Contra un muro a la izquierda (en la V1, a la derecha). Con ← mantenida 5 s contra el muro izquierdo, Pacman se detuvo en (7,1) sin superponerse; luego ↑ lo movió con normalidad (fila 5). (Fantasmas retirados y posiciones preparadas por script para aislar la condición.) | P10: Fecha de cierre | Q10: 46323
A11: CP-008 | B11: Regresión (V1, mutado) | C11: E1 | D11: Alta | E11: Pacman no sale de los límites del mapa | F11: HU-02 | G11: No | H11: Aprobado | I11: Aprobado | J11: =IF(OR(H11="—",I11="",I11="No ejecutado"),"—",IF(H11=I11,"No","Sí")) | K11: Luzzi | L11: 46307 | N11: Mutación: Bordes recorridos en otro orden: abajo, derecha, arriba, izquierda. En los bordes abajo (13,8), derecha (7,15), arriba (1,8) e izquierda (7,1), con la tecla hacia afuera, Pacman no salió del mapa y quedó visible. (Fantasmas retirados y posiciones preparadas por script para aislar la condición.) | P11: Ejecutores | Q11: Luzzi
A12: CP-009 | B12: Regresión (V1, mutado) | C12: E1 | D12: Alta | E12: Los fantasmas clásicos no atraviesan muros | F12: HU-02 | G12: No | H12: Aprobado | I12: Aprobado | J12: =IF(OR(H12="—",I12="",I12="No ejecutado"),"—",IF(H12=I12,"No","Sí")) | K12: Luzzi | L12: 46307 | N12: Mutación: Observación en el nivel 2 en lugar del 1 (solo clásicos al inicio), 60 s. Nivel 2 durante 60 s: ningún fantasma clásico entró a un muro ni salió del mapa (tipos observados: ['classic']). (Vidas repuestas por script para que la partida no termine.) | P12: Forma de ejecución | Q12: Script de navegador (Playwright) que maneja el juego con el teclado y el mouse y lee el estado del juego para verificar los resultados. Cuando una precondición es difícil de alcanzar jugando (posiciones, vidas, mapa reducido), el script la prepara y la observación lo indica.
A13: CP-010 | B13: Regresión (V1, Media/Baja) | C13: E1 | D13: Media | E13: Zona transitable coincidente con el mapa dibujado | F13: HU-02 | G13: No | H13: Aprobado | I13: Aprobado | J13: =IF(OR(H13="—",I13="",I13="No ejecutado"),"—",IF(H13=I13,"No","Sí")) | K13: Luzzi | L13: 46323 | N13: Nivel 1: 107 celdas transitables, todas alcanzables desde la posición de Pacman; 106 marcadas con esfera y la única sin marca es la celda inicial de Pacman (7,8), que ocupa él mismo. Ningún muro tiene esfera. (Recorrido verificado sobre el mapa del juego.)
A14: CP-011 | B14: Regresión (V1, mutado) | C14: E1 | D14: Alta | E14: Consumo de una esfera común | F14: HU-03 | G14: Sí | H14: Aprobado | I14: Aprobado | J14: =IF(OR(H14="—",I14="",I14="No ejecutado"),"—",IF(H14=I14,"No","Sí")) | K14: Luzzi | L14: 46307 | N14: Mutación: Esfera común de otra fila (fila 4). Esfera de (4,3): desapareció; puntaje 0 → 10 (+10); esferas restantes 105 → 104. (Fantasmas retirados y posiciones preparadas por script para aislar la condición.) | P14: Resultados del ciclo 2 (% sobre los casos ejecutados en el ciclo)
A15: CP-012 | B15: Regresión (V1, mutado) | C15: E1 | D15: Alta | E15: Una esfera consumida no reaparece al perder una vida | F15: HU-03 | G15: No | H15: Aprobado | I15: Aprobado | J15: =IF(OR(H15="—",I15="",I15="No ejecutado"),"—",IF(H15=I15,"No","Sí")) | K15: Luzzi | L15: 46307 | N15: Mutación: 15 esferas en lugar de 10, en la fila 10. Pacman consumió 14 esferas en la fila 10; tras perder una vida (3 → 2) la fila sigue despejada (15 de 15 celdas sin esfera). (Fantasmas retirados y posiciones preparadas por script para aislar la condición.) | P15: Estado | Q15: Casos | R15: %
A16: CP-013 | B16: Regresión (V1, Media/Baja) | C16: E1 | D16: Media | E16: Los fantasmas no consumen esferas | F16: HU-03 | G16: No | H16: Aprobado | I16: Aprobado | J16: =IF(OR(H16="—",I16="",I16="No ejecutado"),"—",IF(H16=I16,"No","Sí")) | K16: Luzzi | L16: 46323 | N16: 30 s con Pacman quieto: los fantasmas pasaron por 48 celdas distintas; el contador siguió en 106 → 106 y las esferas del mapa no cambiaron. (Pacman detenido y vidas repuestas por script.) | P16: Aprobado | Q16: =COUNTIF($I$4:$I$132,"Aprobado") | R16: =IFERROR(Q16/SUM($Q$16:$Q$18),0)
A17: CP-014 | B17: Regresión (V1, mutado) | C17: E1 | D17: Alta | E17: Finalización del nivel al consumir la última esfera | F17: HU-04 | G17: Sí | H17: Aprobado | I17: Aprobado | J17: =IF(OR(H17="—",I17="",I17="No ejecutado"),"—",IF(H17=I17,"No","Sí")) | K17: Luzzi | L17: 46307 | N17: Mutación: La última esfera es una de la fila 13. Al consumir la última esfera (13,5) el nivel se completó, la partida se detuvo y se mostró «¡Nivel 1 completado!» con el puntaje. (Mapa reducido a una esfera por script.) | P17: Fallido | Q17: =COUNTIF($I$4:$I$132,"Fallido") | R17: =IFERROR(Q17/SUM($Q$16:$Q$18),0)
A18: CP-015 | B18: Regresión (V1, mutado) | C18: E1 | D18: Alta | E18: El nivel no se completa si queda una esfera grande | F18: HU-04 | G18: No | H18: Aprobado | I18: Aprobado | J18: =IF(OR(H18="—",I18="",I18="No ejecutado"),"—",IF(H18=I18,"No","Sí")) | K18: Luzzi | L18: 46307 | N18: Mutación: La esfera grande pendiente es la de (13,15) en lugar de la de (1,1). Con solo la esfera grande de (13,15) sin consumir, el nivel no se completó y quedan 1 esferas; la partida sigue. (Mapa preparado por script.) | P18: Bloqueado | Q18: =COUNTIF($I$4:$I$132,"Bloqueado") | R18: =IFERROR(Q18/SUM($Q$16:$Q$18),0)
A19: CP-016 | B19: Regresión (V1, mutado) | C19: E1 | D19: Alta | E19: Paso al nivel siguiente conservando puntaje y vidas | F19: HU-04 | G19: Sí | H19: Aprobado | I19: Aprobado | J19: =IF(OR(H19="—",I19="",I19="No ejecutado"),"—",IF(H19=I19,"No","Sí")) | K19: Luzzi | L19: 46307 | N19: Mutación: Se completa el nivel con 3 vidas en lugar de 2. Completado el nivel 1 con 3 vidas y 1200 puntos: empezó el nivel 2 con 1200 puntos y 3 vidas. (Mapa reducido por script.) | P19: Total | Q19: =SUM(Q16:Q18) | R19: =SUM(R16:R18)
A20: CP-017 | B20: Regresión (V1, mutado) | C20: E1 | D20: Alta | E20: Victoria al completar el nivel 3 | F20: HU-04 | G20: Sí | H20: Aprobado | I20: Aprobado | J20: =IF(OR(H20="—",I20="",I20="No ejecutado"),"—",IF(H20=I20,"No","Sí")) | K20: Luzzi | L20: 46307 | N20: Mutación: Partida completa N1 → N2 → N3 con los fantasmas nuevos de la V2. Partida N1 → N2 → N3; en el nivel 3 los fantasmas fueron ['specter', 'jumper', 'naval', 'accelerated']; al consumir la última esfera se mostró «¡Nivel 3 completado!» y luego «¡Victoria!» con el puntaje final. (Mapas reducidos por script.)
A21: CP-018 | B21: Regresión (V1, mutado) | C21: E2 | D21: Alta | E21: Activación automática del PowerUp | F21: HU-05 | G21: Sí | H21: Aprobado | I21: Aprobado | J21: =IF(OR(H21="—",I21="",I21="No ejecutado"),"—",IF(H21=I21,"No","Sí")) | K21: Luzzi | L21: 46307 | N21: Mutación: Esfera grande de (13,1). Al pasar por (13,1) el PowerUp se activó solo; puntaje +50; los fantasmas cambiaron al diseño vulnerable y se alejaron (suma de distancias 48 → 76). (Fantasmas ubicados en el centro por script.)
A22: CP-019 | B22: Regresión (V1, mutado) | C22: E2 | D22: Alta | E22: Duración del PowerUp | F22: HU-05 | G22: No | H22: Aprobado | I22: Aprobado | J22: =IF(OR(H22="—",I22="",I22="No ejecutado"),"—",IF(H22=I22,"No","Sí")) | K22: Luzzi | L22: 46307 | N22: Mutación: Esfera grande de (1,15); observaciones a 7,5 s y 8,5 s. Esfera grande de (1,15): a los 7,5 s los fantasmas seguían vulnerables; a los 8,5 s recuperaron su diseño y volvieron a perseguir. Duración: 8 s.
A23: CP-020 | B23: Regresión (V1, mutado) | C23: E2 | D23: Alta | E23: Los fantasmas huyen durante el PowerUp | F23: HU-05 | G23: No | H23: Aprobado | I23: Aprobado | J23: =IF(OR(H23="—",I23="",I23="No ejecutado"),"—",IF(H23=I23,"No","Sí")) | K23: Luzzi | L23: 46307 | N23: Mutación: Fantasma perseguidor distinto (el rosa). El fantasma rosa venía hacia Pacman por la fila 4; al consumir la esfera grande dejó de acercarse y se alejó (distancia 2 → 7 celdas). (Fantasmas retirados y posiciones preparadas por script para aislar la condición.)
A24: CP-021 | B24: Regresión (V1, Media/Baja) | C24: E2 | D24: Media | E24: Reinicio del temporizador por una segunda esfera grande | F24: HU-05 | G24: No | H24: Aprobado | I24: Aprobado | J24: =IF(OR(H24="—",I24="",I24="No ejecutado"),"—",IF(H24=I24,"No","Sí")) | K24: Luzzi | L24: 46323 | N24: Primera esfera grande (13,1) y, a los 5 s, la segunda (1,1): el PowerUp siguió activo a los 7,8 s del segundo consumo y terminó antes de los 8,2 s (8 s completos, no 3). (Fantasmas retirados y posiciones preparadas por script para aislar la condición.)
A25: CP-022 | B25: Regresión (V1, Media/Baja) | C25: E2 | D25: Media | E25: Reinicio de la escala de puntos por una segunda esfera grande | F25: HU-05 | G25: No | H25: Aprobado | I25: Aprobado | J25: =IF(OR(H25="—",I25="",I25="No ejecutado"),"—",IF(H25=I25,"No","Sí")) | K25: Luzzi | L25: 46323 | N25: Fantasma comido con la primera esfera grande: +200; tras la segunda esfera grande (PowerUp activo), el siguiente fantasma sumó +200: la escala se reinició. (Fantasmas retirados y posiciones preparadas por script para aislar la condición.)
A26: CP-023 | B26: Regresión (V1, mutado) | C26: E2 | D26: Alta | E26: Escala de puntos por fantasmas comidos | F26: HU-06 | G26: Sí | H26: Aprobado | I26: Aprobado | J26: =IF(OR(H26="—",I26="",I26="No ejecutado"),"—",IF(H26=I26,"No","Sí")) | K26: Luzzi | L26: 46307 | N26: Mutación: Se usa la esfera grande de (13,15). Con la esfera grande de (13,15), los cuatro fantasmas comidos sumaron [200, 400, 800, 1600]. (Fantasmas retirados y posiciones preparadas por script para aislar la condición.)
A27: CP-024 | B27: Regresión (V1, mutado) | C27: E2 | D27: Alta | E27: Reinicio de la escala al terminar el PowerUp | F27: HU-06 | G27: No | H27: Aprobado | I27: Aprobado | J27: =IF(OR(H27="—",I27="",I27="No ejecutado"),"—",IF(H27=I27,"No","Sí")) | K27: Luzzi | L27: 46307 | N27: Mutación: Segundo PowerUp con una esfera grande distinta. Primer PowerUp (13,15): fantasma +200; terminado el PowerUp, segundo PowerUp con la esfera de (1,1): fantasma +200. (Fantasmas retirados y posiciones preparadas por script para aislar la condición.)
A28: CP-025 | B28: Regresión (V1, mutado) | C28: E2 | D28: Alta | E28: Comer un fantasma no descuenta vidas | F28: HU-06 | G28: No | H28: Aprobado | I28: Aprobado | J28: =IF(OR(H28="—",I28="",I28="No ejecutado"),"—",IF(H28=I28,"No","Sí")) | K28: Luzzi | L28: 46307 | N28: Mutación: Con 2 vidas en lugar de 3. Con 2 vidas y PowerUp activo, el fantasma tocado desapareció; vidas 2 → 2; el nivel no se reinició (Pacman siguió en la fila 4). (Vidas fijadas en 2 por script.)
A29: CP-026 | B29: Regresión (V1, Media/Baja) | C29: E2 | D29: Media | E29: Reaparición del fantasma comido | F29: HU-06 | G29: No | H29: Aprobado | I29: Aprobado | J29: =IF(OR(H29="—",I29="",I29="No ejecutado"),"—",IF(H29=I29,"No","Sí")) | K29: Luzzi | L29: 46323 | N29: El fantasma rojo comido desapareció y reapareció a los 5.00 s en su punto de reaparición (1, 1); luego siguió moviéndose. (PowerUp prolongado por script para observar la reaparición.)
A30: CP-027 | B30: Regresión (V1, Media/Baja) | C30: E2 | D30: Media | E30: Fantasma que reaparece con el PowerUp aún activo | F30: HU-06 | G30: No | H30: Aprobado | I30: Aprobado | J30: =IF(OR(H30="—",I30="",I30="No ejecutado"),"—",IF(H30=I30,"No","Sí")) | K30: Luzzi | L30: 46323 | N30: Primer bocado +200; el fantasma reapareció a los 5.03 s con el PowerUp activo y en estado vulnerable; comido otra vez sumó +400: la escala siguió. (Fantasmas retirados y posiciones preparadas por script para aislar la condición.)
A31: CP-028 | B31: Regresión (V1, Media/Baja) | C31: E2 | D31: Media | E31: Parpadeo en los últimos 2 segundos del PowerUp | F31: HU-07 | G31: No | H31: Aprobado | I31: Aprobado | J31: =IF(OR(H31="—",I31="",I31="No ejecutado"),"—",IF(H31=I31,"No","Sí")) | K31: Luzzi | L31: 46323 | N31: A los 5 s los fantasmas se veían azules fijos (colores muestreados: ['azul']); a los 7 s alternaban azul y blanco (parpadeo, colores: ['azul', 'blanco']), distinto del azul fijo y del color normal. (Capturas CP-028-5s y CP-028-7s; colores leídos del canvas.)
... A36: CP-033 | B36: Regresión (V1, mutado) | C36: E2 | D36: Alta | E36: Reanudación del nivel tras perder una vida | F36: HU-08 | G36: No | H36: Aprobado | I36: Aprobado | J36: =IF(OR(H36="—",I36="",I36="No ejecutado"),"—",IF(H36=I36,"No","Sí")) | K36: Luzzi | L36: 46307 | N36: Mutación: Con 20 esferas consumidas. Con 20 esferas consumidas se perdió una vida: siguió el nivel 1, puntaje 200 → 200, las esferas consumidas siguen ausentes y los personajes volvieron a sus posiciones iniciales. (Fantasmas retirados y posiciones preparadas por script para aislar la condición.)
A37: CP-034 | B37: Confirmación DEF-001 | C37: E3 | D37: Media | E37: Presentación del contador de vidas | F37: HU-09 | G37: No | H37: Fallido | I37: Aprobado | J37: =IF(OR(H37="—",I37="",I37="No ejecutado"),"—",IF(H37=I37,"No","Sí")) | K37: Luzzi | L37: 46307 | M37: DEF-001 | N37: Las vidas se muestran abajo a la izquierda, debajo del mapa, como 3 íconos de Pacman (sin número); al perder una vida quedan 2. CP-034: Fallido en Entrega 1 → Aprobado. | P37: Comparación de resultados por entrega (%)
A38: CP-035 | B38: Regresión (V1, Media/Baja) | C38: E3 | D38: Media | E38: Actualización inmediata del contador de vidas | F38: HU-09 | G38: No | H38: Aprobado | I38: Aprobado | J38: =IF(OR(H38="—",I38="",I38="No ejecutado"),"—",IF(H38=I38,"No","Sí")) | K38: Luzzi | L38: 46323 | N38: Íconos de vidas tras cada pérdida: 3 → 2 → 1 → 0; el contador se actualizó en el momento de cada pérdida (la tercera terminó en Game Over). (Fantasmas retirados y posiciones preparadas por script para aislar la condición.) | P38: Estado | Q38: Entrega 1 (V1) | R38: Entrega 2 (V2) | S38: Casos E1 / E2
A39: CP-036 | B39: Regresión (V1, mutado) | C39: E3 | D39: Alta | E39: Game Over al perder la tercera vida | F39: HU-10 | G39: Sí | H39: Aprobado | I39: Aprobado | J39: =IF(OR(H39="—",I39="",I39="No ejecutado"),"—",IF(H39=I39,"No","Sí")) | K39: Luzzi | L39: 46307 | N39: Mutación: Última vida perdida en el nivel 2. Última vida perdida en el nivel 2: se mostró «Game Over» con el puntaje final (0); 5 s después la partida seguía terminada, sin reiniciarse ni reanudarse. (Vidas fijadas en 1 por script.) | P39: Aprobado | Q39: 0.96969697 | R39: =R16 | S39: ="64 / "&Q16
A40: CP-037 | B40: Regresión (V1, Media/Baja) | C40: E3 | D40: Media | E40: Game Over en un nivel distinto del primero | F40: HU-10 | G40: No | H40: Aprobado | I40: Aprobado | J40: =IF(OR(H40="—",I40="",I40="No ejecutado"),"—",IF(H40=I40,"No","Sí")) | K40: Luzzi | L40: 46323 | N40: Última vida perdida en el nivel 3: pantalla «Game Over» con el puntaje final y «Volver a jugar», igual que en el nivel 1; la partida no se reanudó. (Vidas fijadas en 1 por script.) | P40: Fallido | Q40: 0.015151515 | R40: =R17 | S40: ="1 / "&Q17
A41: CP-038 | B41: Regresión (V1, Media/Baja) | C41: E3 | D41: Media | E41: Puntaje visible y actualizado en el HUD | F41: HU-11 | G41: Sí | H41: Aprobado | I41: Aprobado | J41: =IF(OR(H41="—",I41="",I41="No ejecutado"),"—",IF(H41=I41,"No","Sí")) | K41: Luzzi | L41: 46323 | N41: HUD: puntaje inicial 0; después de cada acción [10, 60, 260] (incrementos [10, 50, 200]: esfera común, esfera grande y fantasma). (Fantasmas retirados y posiciones preparadas por script para aislar la condición.) | P41: Bloqueado | Q41: 0.015151515 | R41: =R18 | S41: ="1 / "&Q18
A42: CP-039 | B42: Regresión (V1, Media/Baja) | C42: E3 | D42: Media | E42: El puntaje no disminuye ni se reinicia entre niveles | F42: HU-11 | G42: No | H42: Aprobado | I42: Aprobado | J42: =IF(OR(H42="—",I42="",I42="No ejecutado"),"—",IF(H42=I42,"No","Sí")) | K42: Luzzi | L42: 46323 | N42: Puntaje 60; tras perder una vida: 60; al completar el nivel 1: 1240; al iniciar el nivel 2: 1240. Nunca disminuyó. (Mapa reducido por script para completar el nivel.) | P42: Fuente Entrega 1: reporte de ejecución de la Entrega 1 (66 casos: 64 aprobados, 1 fallido, 1 bloqueado).
A43: CP-040 | B43: Regresión (V1, Media/Baja) | C43: E3 | D43: Media | E43: Consumo de una fruta | F43: HU-12 | G43: Sí | H43: Aprobado | I43: Aprobado | J43: =IF(OR(H43="—",I43="",I43="No ejecutado"),"—",IF(H43=I43,"No","Sí")) | K43: Luzzi | L43: 46323 | N43: Fruta aparecida en (9,8) en el nivel 3: Pacman la consumió, desapareció del mapa, el puntaje subió +100 y el contador de esferas quedó en 124 → 124. (Esfera de la celda retirada por script para medir solo la fruta.)
A44: CP-041 | B44: Regresión (V1, Media/Baja) | C44: E3 | D44: Baja | E44: Desaparición de una fruta no consumida | F44: HU-12 | G44: No | H44: Aprobado | I44: Aprobado | J44: =IF(OR(H44="—",I44="",I44="No ejecutado"),"—",IF(H44=I44,"No","Sí")) | K44: Luzzi | L44: 46323 | N44: Fruta aparecida en (9,4): a los 14 s seguía en el mapa; a los 16 s ya no estaba.
...

Sheet Registro de defectos
A1: GhostMan - Entrega 2 - Registro de defectos (V1 y V2, ciclo 2)
A2: Una fila por defecto, en orden de detección. Los defectos de la V2 continúan la numeración de la V1 (sección 12 de la Entrega 02). Campos de la sección 13.3; severidad y prioridad según 13.1; estado según 13.2. El detalle completo va en la hoja con el ID del defecto.
A3: Todo defecto debe ser confirmado por un integrante distinto del que lo reportó antes de pasar a corrección, y verificado por un integrante distinto antes de cerrarse (13.2).
A4: ID | B4: Título | C4: Caso de prueba | D4: HU | E4: Severidad | F4: Prioridad | G4: Estado | H4: Versión / commit | I4: Entorno (navegador, resolución) | J4: Reproducibilidad | K4: Reportado por | L4: Confirmado por | M4: Fecha | N4: Observaciones | Q4: Defectos por severidad
A5: DEF-001 | B5: El contador de vidas se muestra arriba a la derecha como círculos amarillos en lugar de íconos de Pacman abajo a la izquierda | C5: CP-034 | D5: HU-09 | E5: Menor | F5: Media | G5: Verificado | H5: V1 - commit a completar (corregido en V2 - 7ec70df) | I5: Chrome 154 escritorio (macOS), 1291 × 693 | J5: Siempre | K5: Rodriguez Castro | L5: Luzzi | M5: 46294 | N5: Detectado en la Entrega 1. Corregido en el commit 7ec70df: las vidas del modo Pacman pasan a una barra debajo del mapa, abajo a la izquierda, con íconos de Pacman. Verificado el 12/10/2026 con la prueba de confirmación (CP-034, Aprobado, Chromium 141). Además, CP-047 de la regresión registró la barra en los tres niveles. | Q5: Bloqueante | R5: =COUNTIF($E$5:$E$104,"Bloqueante")
A6: DEF-002 | B6: El menú principal elige la opción que tiene el puntero encima al cargar la página, aunque el mouse no se haya movido | C6: Exploratoria | D6: HU-22 | E6: Menor | F6: Media | G6: Corregido | H6: V2 - b451d52 (corregido en 65df127) | I6: Chromium sin interfaz (Linux), 700 × 600 | J6: Siempre | K6: Luzzi | M6: 46307 | N6: Lo detectó el script scripts/verify/ui/inc10-menu-carrusel.js: tras elegir Modo GhostMan con un clic y recargar la página, Enter abre el carrusel en lugar de iniciar el Modo PacMan, porque el puntero quedó sobre esa opción. Corrección: la selección cambia solo con un movimiento real del mouse. La prueba de confirmación del 12/10/2026 dio Aprobado; falta que otro integrante lo confirme y lo verifique para pasarlo a Verificado. | Q6: Crítica | R6: =COUNTIF($E$5:$E$104,"Crítica")
A7: DEF-003 | B7: En modo GhostMan, el toque de un fantasma de la IA no le descuenta una vida a Pacman sin PowerUp | C7: Exploratoria | D7: HU-25 | E7: Mayor | F7: Media | G7: Rechazado | H7: V2 - 7ec70df | I7: Completar (navegador y resolución con los que probó Tsai) | J7: Siempre | K7: Tsai | L7: Luzzi | M7: 46307 | N7: Reportado por Tsai al probar el juego. Al triarlo se rechazó: el comportamiento es el especificado. La HU-25 dice «Solo cuentan las derrotas producidas por el fantasma del jugador: las producidas por los fantasmas de la IA no incrementan el contador», y la decisión 19 (sección 5 de la Entrega 02) define que el toque de un fantasma de la IA devuelve a Pacman a su posición inicial sin descontarle vidas. Como en modo GhostMan las vidas de Pacman son el contador de derrotas (decisión 18), descontarlas por la IA contradiría la HU-25. Lo cubren CP-078 y CP-144 (Aprobados en el ciclo 2). Si el equipo quiere cambiar la regla, va como cambio de especificación (decisión 19), no como defecto. | Q7: Mayor | R7: =COUNTIF($E$5:$E$104,"Mayor")
Q8: Menor | R8: =COUNTIF($E$5:$E$104,"Menor")
Q9: Trivial | R9: =COUNTIF($E$5:$E$104,"Trivial")
Q10: Total | R10: =COUNTA($A$5:$A$104)
Q12: Defectos por estado
Q13: Nuevo | R13: =COUNTIF($G$5:$G$104,"Nuevo")
Q14: Confirmado | R14: =COUNTIF($G$5:$G$104,"Confirmado")
Q15: No reproducible | R15: =COUNTIF($G$5:$G$104,"No reproducible")
Q16: En corrección | R16: =COUNTIF($G$5:$G$104,"En corrección")
Q17: Corregido | R17: =COUNTIF($G$5:$G$104,"Corregido")
Q18: Verificado | R18: =COUNTIF($G$5:$G$104,"Verificado")
Q19: Diferido | R19: =COUNTIF($G$5:$G$104,"Diferido")
Q20: Rechazado | R20: =COUNTIF($G$5:$G$104,"Rechazado")
Q22: Defectos por versión en que se detectaron
Q23: V1 | R23: =COUNTIF($H$5:$H$104,"V1*")
Q24: V2 | R24: =COUNTIF($H$5:$H$104,"V2*")
Q26: Defectos de la V2 por funcionalidad (sin rechazados)
Q27: Menú y elección del modo (HU-22) | R27: =COUNTIFS($D$5:$D$104,"HU-22",$H$5:$H$104,"V2*",$G$5:$G$104,"<>Rechazado")
Q28: Carrusel de fantasmas (HU-23) | R28: =COUNTIFS($D$5:$D$104,"HU-23",$H$5:$H$104,"V2*",$G$5:$G$104,"<>Rechazado")
Q29: Control del fantasma e IA de Pacman (HU-24) | R29: =COUNTIFS($D$5:$D$104,"HU-24",$H$5:$H$104,"V2*",$G$5:$G$104,"<>Rechazado")
Q30: Reglas del modo GhostMan: derrota, victoria, puntaje (HU-25 a HU-27) | R30: =COUNTIFS($D$5:$D$104,"HU-25",$H$5:$H$104,"V2*",$G$5:$G$104,"<>Rechazado")+COUNTIFS($D$5:$D$104,"HU-26",$H$5:$H$104,"V2*",$G$5:$G$104,"<>Rechazado")+COUNTIFS($D$5:$D$104,"HU-27",$H$5:$H$104,"V2*",$G$5:$G$104,"<>Rechazado")
Q31: Espectro (HU-28) | R31: =COUNTIFS($D$5:$D$104,"HU-28",$H$5:$H$104,"V2*",$G$5:$G$104,"<>Rechazado")
Q32: Saltarín (HU-29) | R32: =COUNTIFS($D$5:$D$104,"HU-29",$H$5:$H$104,"V2*",$G$5:$G$104,"<>Rechazado")
Q33: Naval y frutas falsas (HU-30) | R33: =COUNTIFS($D$5:$D$104,"HU-30",$H$5:$H$104,"V2*",$G$5:$G$104,"<>Rechazado")
Q34: Acelerado (HU-31) | R34: =COUNTIFS($D$5:$D$104,"HU-31",$H$5:$H$104,"V2*",$G$5:$G$104,"<>Rechazado")
Q35: Indicador de poder (HU-32) | R35: =COUNTIFS($D$5:$D$104,"HU-32",$H$5:$H$104,"V2*",$G$5:$G$104,"<>Rechazado")
Q36: Dificultad del modo GhostMan: paredes y esferas grandes (HU-33, HU-34) | R36: =COUNTIFS($D$5:$D$104,"HU-33",$H$5:$H$104,"V2*",$G$5:$G$104,"<>Rechazado")+COUNTIFS($D$5:$D$104,"HU-34",$H$5:$H$104,"V2*",$G$5:$G$104,"<>Rechazado")
Q37: Fantasmas especiales en el modo Pacman (HU-43) | R37: =COUNTIFS($D$5:$D$104,"HU-43",$H$5:$H$104,"V2*",$G$5:$G$104,"<>Rechazado")
Q38: Total V2 | R38: =SUM(R27:R37)
Q40: Defectos por épica (según el CP)
Q41: E1 — Núcleo de juego y movimiento | R41: =COUNTIF($D$5:$D$104,"HU-01")+COUNTIF($D$5:$D$104,"HU-02")+COUNTIF($D$5:$D$104,"HU-03")+COUNTIF($D$5:$D$104,"HU-04")
Q42: E2 — PowerUp e interacción con fantasmas | R42: =COUNTIF($D$5:$D$104,"HU-05")+COUNTIF($D$5:$D$104,"HU-06")+COUNTIF($D$5:$D$104,"HU-07")+COUNTIF($D$5:$D$104,"HU-08")
Q43: E3 — Vidas, puntaje y fin de partida | R43: =COUNTIF($D$5:$D$104,"HU-09")+COUNTIF($D$5:$D$104,"HU-10")+COUNTIF($D$5:$D$104,"HU-11")+COUNTIF($D$5:$D$104,"HU-12")+COUNTIF($D$5:$D$104,"HU-13")+COUNTIF($D$5:$D$104,"HU-14")
Q44: E4 — Niveles y progresión de dificultad | R44: =COUNTIF($D$5:$D$104,"HU-15")+COUNTIF($D$5:$D$104,"HU-16")+COUNTIF($D$5:$D$104,"HU-17")+COUNTIF($D$5:$D$104,"HU-18")+COUNTIF($D$5:$D$104,"HU-19")+COUNTIF($D$5:$D$104,"HU-43")
...

Sheet CP-001
A1: Test Case ID | B1: CP-001 | C1: Descripción / Funcionalidad | D1: HU-01 · Mover a Pacman por el mapa | G1: Registro de ejecución
A2: Creado por | B2: Cruz, Luzzi (mutación: Luzzi) | C2: Versión | D2: 2 | G2: Ciclo | H2: Fecha | I2: Ejecutor | J2: Estado | K2: Resultado obtenido | L2: Defecto
A3: Reporte de ejecución 2 | C3: Estado en la Entrega 2 | D3: =IFERROR(IF(INDEX('Reporte de ejecución - Entrega2'!$I$4:$I$132,MATCH($B$1,'Reporte de ejecución - Entrega2'!$A$4:$A$132,0))="","Sin ejecutar",INDEX('Reporte de ejecución - Entrega2'!$I$4:$I$132,MATCH($B$1,'Reporte de ejecución - Entrega2'!$A$4:$A$132,0))),"Sin ejecutar") | G3: Ciclo 1 | H3: 46294 | I3: Rodriguez Castro | J3: Aprobado | K3: Las 4 direcciones responden. Corrida 1: ← mueve a la izquierda, ↑ gira hacia arriba en la primera intersección libre, → gira a la derecha. Corrida 2: → desde la posición inicial y ↓ gira hacia abajo en la primera intersección libre. ↓ se verificó en una corrida aparte porque en la secuencia ←↑→↓ un fantasma intercepta a Pacman antes de la intersección (comportamiento esperado, no es defecto). La partida inicia directamente en modo Pacman, sin pantalla de selección.
C4: Estado en la Entrega 1 | D4: Aprobado | G4: Ciclo 2 | H4: 46307 | I4: Luzzi | J4: Aprobado | K4: Desde el cruce (4,6), ↓ → ↑ ← desplazaron a Pacman hacia abajo, derecha, arriba e izquierda respectivamente. (Fantasmas retirados y posiciones preparadas por script para aislar la condición.)
A5: Prioridad (Alta, Media, Baja) | B5: Alta | C5: Técnica de diseño | D5: Partición de equivalencia | G5: Ciclo 3
G6: Ciclo 1 = Entrega 1 (V1). Ciclo 2 = Entrega 2 (V2): ejecución con script de navegador; las precondiciones preparadas por script se aclaran en el resultado obtenido.
A7: # | B7: Pre-requisitos | D7: Datos de prueba
A8: 1 | B8: Abrir la aplicación en un navegador de escritorio. | D8: Entorno: | E8: Build del commit 7ec70df (V2)
A9: 2 | B9: Elegir «Modo PacMan» en el menú principal y presionar Enter (HU-22). | D9: Navegador: | E9: Chromium 141 de escritorio
A10: 3 | B10: Partida en curso (N1). | D10: Modo de juego: | E10: Pacman
A12: Título del CP | B12: Movimiento de Pacman con las flechas
A15: Historias de Usuario | B15: HU-01 | C15: Épica | D15: E1 — Núcleo de juego y movimiento
A16: Estado Automatización | B16: Automatizado (script de navegador, Entrega 2) | C16: Camino feliz | D16: Sí
A18: Mutación (Entrega 2) | B18: Secuencia invertida: ↓ → ↑ ← (la V1 usó ← ↑ → ↓).
A20: Pasos # | B20: Detalle de pasos | D20: Resultado esperado
A21: 1 | B21: Presionar ←. | D21: Pacman se desplaza hacia la izquierda.
A22: 2 | B22: Presionar ↑. | D22: Pacman se desplaza hacia arriba.
A23: 3 | B23: Presionar →. | D23: Pacman se desplaza hacia la derecha.
A24: 4 | B24: Presionar ↓. | D24: Pacman se desplaza en la dirección de cada tecla presionada, siempre que el camino esté libre.
A25: El caso se aprueba solo si se cumple todo el resultado esperado del último paso (en negrita); si cualquier parte no se cumple, se registra como Fallido.

Sheet CP-002
A1: Test Case ID | B1: CP-002 | C1: Descripción / Funcionalidad | D1: HU-01 · Mover a Pacman por el mapa | G1: Registro de ejecución
A2: Creado por | B2: Cruz, Luzzi (mutación: Luzzi) | C2: Versión | D2: 2 | G2: Ciclo | H2: Fecha | I2: Ejecutor | J2: Estado | K2: Resultado obtenido | L2: Defecto
A3: Reporte de ejecución 2 | C3: Estado en la Entrega 2 | D3: =IFERROR(IF(INDEX('Reporte de ejecución - Entrega2'!$I$4:$I$132,MATCH($B$1,'Reporte de ejecución - Entrega2'!$A$4:$A$132,0))="","Sin ejecutar",INDEX('Reporte de ejecución - Entrega2'!$I$4:$I$132,MATCH($B$1,'Reporte de ejecución - Entrega2'!$A$4:$A$132,0))),"Sin ejecutar") | G3: Ciclo 1 | H3: 46294 | I3: Rodriguez Castro | J3: Aprobado | K3: Las 4 teclas responden igual que las flechas. Corrida 1: A izquierda, W arriba, D derecha (mismas trayectorias y tiempos que ←↑→ en CP-001). Corrida 2: D desde la posición inicial y S gira hacia abajo en la primera intersección libre (idéntica a →↓). S se verificó aparte por la intercepción del fantasma.
C4: Estado en la Entrega 1 | D4: Aprobado | G4: Ciclo 2 | H4: 46307 | I4: Luzzi | J4: Aprobado | K4: S D W A produjeron el mismo desplazamiento que ↓ → ↑ ← (abajo, derecha, arriba, izquierda). (Fantasmas retirados y posiciones preparadas por script para aislar la condición.)
A5: Prioridad (Alta, Media, Baja) | B5: Alta | C5: Técnica de diseño | D5: Partición de equivalencia | G5: Ciclo 3
G6: Ciclo 1 = Entrega 1 (V1). Ciclo 2 = Entrega 2 (V2): ejecución con script de navegador; las precondiciones preparadas por script se aclaran en el resultado obtenido.
A7: # | B7: Pre-requisitos | D7: Datos de prueba
A8: 1 | B8: Abrir la aplicación en un navegador de escritorio. | D8: Entorno: | E8: Build del commit 7ec70df (V2)
A9: 2 | B9: Elegir «Modo PacMan» en el menú principal y presionar Enter (HU-22). | D9: Navegador: | E9: Chromium 141 de escritorio
A10: 3 | B10: Partida en curso (N1). | D10: Modo de juego: | E10: Pacman
A12: Título del CP | B12: Movimiento de Pacman con WASD
A15: Historias de Usuario | B15: HU-01 | C15: Épica | D15: E1 — Núcleo de juego y movimiento
A16: Estado Automatización | B16: Automatizado (script de navegador, Entrega 2) | C16: Camino feliz | D16: Sí
A18: Mutación (Entrega 2) | B18: Secuencia invertida: S D W A.
A20: Pasos # | B20: Detalle de pasos | D20: Resultado esperado
A21: 1 | B21: Presionar A. | D21: Pacman se desplaza hacia la izquierda, igual que con ←.
A22: 2 | B22: Presionar W. | D22: Pacman se desplaza hacia arriba, igual que con ↑.
A23: 3 | B23: Presionar D. | D23: Pacman se desplaza hacia la derecha, igual que con →.
A24: 4 | B24: Presionar S. | D24: Cada tecla produce el mismo desplazamiento que ←, ↑, → y ↓ respectivamente.
A25: El caso se aprueba solo si se cumple todo el resultado esperado del último paso (en negrita); si cualquier parte no se cumple, se registra como Fallido.

Sheet CP-003
A1: Test Case ID | B1: CP-003 | C1: Descripción / Funcionalidad | D1: HU-01 · Mover a Pacman por el mapa | G1: Registro de ejecución
A2: Creado por | B2: Cruz, Luzzi (mutación: Luzzi) | C2: Versión | D2: 2 | G2: Ciclo | H2: Fecha | I2: Ejecutor | J2: Estado | K2: Resultado obtenido | L2: Defecto
A3: Reporte de ejecución 2 | C3: Estado en la Entrega 2 | D3: =IFERROR(IF(INDEX('Reporte de ejecución - Entrega2'!$I$4:$I$132,MATCH($B$1,'Reporte de ejecución - Entrega2'!$A$4:$A$132,0))="","Sin ejecutar",INDEX('Reporte de ejecución - Entrega2'!$I$4:$I$132,MATCH($B$1,'Reporte de ejecución - Entrega2'!$A$4:$A$132,0))),"Sin ejecutar") | G3: Ciclo 1 | H3: 46294 | I3: Rodriguez Castro | J3: Aprobado | K3: Aprobado. Avance continuo verificado en el registro de posición cuadro a cuadro. A los 3,0 s un fantasma alcanzó a Pacman, que ya estaba detenido contra el muro; no afecta al resultado.
C4: Estado en la Entrega 1 | D4: Aprobado | G4: Ciclo 2 | H4: 46307 | I4: Luzzi | J4: Aprobado | K4: Tras un toque de ↓ en (10,6), Pacman siguió bajando sin mantener la tecla hasta el muro inferior (fila 13) y se detuvo ahí. (Fantasmas retirados y posiciones preparadas por script para aislar la condición.)
A5: Prioridad (Alta, Media, Baja) | B5: Alta | C5: Técnica de diseño | D5: Adivinación de errores | G5: Ciclo 3
G6: Ciclo 1 = Entrega 1 (V1). Ciclo 2 = Entrega 2 (V2): ejecución con script de navegador; las precondiciones preparadas por script se aclaran en el resultado obtenido.
A7: # | B7: Pre-requisitos | D7: Datos de prueba
A8: 1 | B8: Abrir la aplicación en un navegador de escritorio. | D8: Entorno: | E8: Build del commit 7ec70df (V2)
A9: 2 | B9: Elegir «Modo PacMan» en el menú principal y presionar Enter (HU-22). | D9: Navegador: | E9: Chromium 141 de escritorio
A10: 3 | B10: Partida en curso (N1), Pacman en un corredor libre. | D10: Modo de juego: | E10: Pacman
A12: Título del CP | B12: Avance continuo sin mantener la tecla
A15: Historias de Usuario | B15: HU-01 | C15: Épica | D15: E1 — Núcleo de juego y movimiento
A16: Estado Automatización | B16: Automatizado (script de navegador, Entrega 2) | C16: Camino feliz | D16: Sí
A18: Mutación (Entrega 2) | B18: Se usa la dirección ↓ desde una celda distinta a la de la V1 (fila 10).
A20: Pasos # | B20: Detalle de pasos | D20: Resultado esperado
A21: 1 | B21: Presionar y liberar de inmediato la tecla de una dirección libre. | D21: Pacman comienza a avanzar en la dirección indicada.
A22: 2 | B22: Observar durante 3 segundos sin tocar el teclado. | D22: Pacman sigue avanzando en esa dirección durante los 3 segundos, hasta encontrar un muro.
A23: El caso se aprueba solo si se cumple todo el resultado esperado del último paso (en negrita); si cualquier parte no se cumple, se registra como Fallido.

Sheet CP-004
A1: Test Case ID | B1: CP-004 | C1: Descripción / Funcionalidad | D1: HU-01 · Mover a Pacman por el mapa | G1: Registro de ejecución
A2: Creado por | B2: Cruz, Luzzi | C2: Versión | D2: 1 | G2: Ciclo | H2: Fecha | I2: Ejecutor | J2: Estado | K2: Resultado obtenido | L2: Defecto
A3: Reporte de ejecución 2 | C3: Estado en la Entrega 2 | D3: =IFERROR(IF(INDEX('Reporte de ejecución - Entrega2'!$I$4:$I$132,MATCH($B$1,'Reporte de ejecución - Entrega2'!$A$4:$A$132,0))="","Sin ejecutar",INDEX('Reporte de ejecución - Entrega2'!$I$4:$I$132,MATCH($B$1,'Reporte de ejecución - Entrega2'!$A$4:$A$132,0))),"Sin ejecutar") | G3: Ciclo 1 | H3: 46294 | I3: Rodriguez Castro | J3: Aprobado | K3: Aprobado. La tecla se presionó a unas 4,5 celdas de la intersección, no a 3 como indica el prerrequisito; el comportamiento verificado es el mismo (giro postergado sin frenar).
C4: Estado en la Entrega 1 | D4: Aprobado | G4: Ciclo 2 | H4: 46323 | I4: Luzzi | J4: Aprobado | K4: Avanzando a la derecha por la fila 4 desde (4,3), ↑ presionado 3 celdas antes de la intersección: Pacman siguió en horizontal sin detenerse y giró hacia arriba al llegar a la columna 6. (Fantasmas retirados y posiciones preparadas por script para aislar la condición.)
A5: Prioridad (Alta, Media, Baja) | B5: Media | C5: Técnica de diseño | D5: Transición de estados | G5: Ciclo 3
G6: Ciclo 1 = Entrega 1 (V1). Ciclo 2 = Entrega 2 (V2): ejecución con script de navegador; las precondiciones preparadas por script se aclaran en el resultado obtenido.
A7: # | B7: Pre-requisitos | D7: Datos de prueba
A8: 1 | B8: Abrir la aplicación en un navegador de escritorio. | D8: Entorno: | E8: Build del commit 7ec70df (V2)
A9: 2 | B9: Elegir «Modo PacMan» en el menú principal y presionar Enter (HU-22). | D9: Navegador: | E9: Chromium 141 de escritorio
A10: 3 | B10: Partida en curso (N1), Pacman avanzando por un corredor horizontal con una intersección hacia arriba a 3 celdas de distancia. | D10: Modo de juego: | E10: Pacman
A12: Título del CP | B12: Giro postergado hasta la primera celda posible
A15: Historias de Usuario | B15: HU-01 | C15: Épica | D15: E1 — Núcleo de juego y movimiento
A16: Estado Automatización | B16: Automatizado (script de navegador, Entrega 2) | C16: Camino feliz | D16: No
A18: Pasos # | B18: Detalle de pasos | D18: Resultado esperado
A19: 1 | B19: Con Pacman en movimiento horizontal, presionar ↑ antes de llegar a la intersección. | D19: Pacman continúa avanzando en horizontal y gira hacia arriba al llegar a la intersección, sin detenerse en el trayecto.
A20: El caso se aprueba solo si se cumple todo el resultado esperado del último paso (en negrita); si cualquier parte no se cumple, se registra como Fallido.

Sheet CP-005
A1: Test Case ID | B1: CP-005 | C1: Descripción / Funcionalidad | D1: HU-01 · Mover a Pacman por el mapa | G1: Registro de ejecución
A2: Creado por | B2: Cruz, Luzzi (mutación: Luzzi) | C2: Versión | D2: 2 | G2: Ciclo | H2: Fecha | I2: Ejecutor | J2: Estado | K2: Resultado obtenido | L2: Defecto
A3: Reporte de ejecución 2 | C3: Estado en la Entrega 2 | D3: =IFERROR(IF(INDEX('Reporte de ejecución - Entrega2'!$I$4:$I$132,MATCH($B$1,'Reporte de ejecución - Entrega2'!$A$4:$A$132,0))="","Sin ejecutar",INDEX('Reporte de ejecución - Entrega2'!$I$4:$I$132,MATCH($B$1,'Reporte de ejecución - Entrega2'!$A$4:$A$132,0))),"Sin ejecutar") | G3: Ciclo 1 | H3: 46294 | I3: Rodriguez Castro | J3: Aprobado | K3: Aprobado. No se detuvo ni quedó trabado. El giro posterior en (7,15) corresponde al giro postergado (CP-004).
C4: Estado en la Entrega 1 | D4: Aprobado | G4: Ciclo 2 | H4: 46307 | I4: Luzzi | J4: Aprobado | K4: Avanzando a la derecha por la fila 10 con muro debajo (11,2), ↓ no lo detuvo: siguió hacia la derecha (posición 2.68). (Fantasmas retirados y posiciones preparadas por script para aislar la condición.)
A5: Prioridad (Alta, Media, Baja) | B5: Alta | C5: Técnica de diseño | D5: Valores límite | G5: Ciclo 3
G6: Ciclo 1 = Entrega 1 (V1). Ciclo 2 = Entrega 2 (V2): ejecución con script de navegador; las precondiciones preparadas por script se aclaran en el resultado obtenido.
A7: # | B7: Pre-requisitos | D7: Datos de prueba
A8: 1 | B8: Abrir la aplicación en un navegador de escritorio. | D8: Entorno: | E8: Build del commit 7ec70df (V2)
A9: 2 | B9: Elegir «Modo PacMan» en el menú principal y presionar Enter (HU-22). | D9: Navegador: | E9: Chromium 141 de escritorio
A10: 3 | B10: Partida en curso (N1), Pacman avanzando por un corredor horizontal con muros arriba y abajo. | D10: Modo de juego: | E10: Pacman
A12: Título del CP | B12: Dirección bloqueada por un muro
A15: Historias de Usuario | B15: HU-01 | C15: Épica | D15: E1 — Núcleo de juego y movimiento
A16: Estado Automatización | B16: Automatizado (script de navegador, Entrega 2) | C16: Camino feliz | D16: No
A18: Mutación (Entrega 2) | B18: Se ejecuta en la fila 10 con ↓ bloqueado, en lugar de ↑.
A20: Pasos # | B20: Detalle de pasos | D20: Resultado esperado
A21: 1 | B21: Presionar ↑ con el muro inmediatamente arriba. | D21: Pacman mantiene su dirección horizontal de avance. No se detiene ni queda trabado.
A22: El caso se aprueba solo si se cumple todo el resultado esperado del último paso (en negrita); si cualquier parte no se cumple, se registra como Fallido.

Sheet CP-006
A1: Test Case ID | B1: CP-006 | C1: Descripción / Funcionalidad | D1: HU-01 · Mover a Pacman por el mapa | G1: Registro de ejecución
A2: Creado por | B2: Cruz, Luzzi | C2: Versión | D2: 1 | G2: Ciclo | H2: Fecha | I2: Ejecutor | J2: Estado | K2: Resultado obtenido | L2: Defecto
A3: Reporte de ejecución 2 | C3: Estado en la Entrega 2 | D3: =IFERROR(IF(INDEX('Reporte de ejecución - Entrega2'!$I$4:$I$132,MATCH($B$1,'Reporte de ejecución - Entrega2'!$A$4:$A$132,0))="","Sin ejecutar",INDEX('Reporte de ejecución - Entrega2'!$I$4:$I$132,MATCH($B$1,'Reporte de ejecución - Entrega2'!$A$4:$A$132,0))),"Sin ejecutar") | G3: Ciclo 1 | H3: 46294 | I3: Rodriguez Castro | J3: Aprobado | K3: Aprobado. Inversión inmediata, sin llegar a una intersección.
C4: Estado en la Entrega 1 | D4: Aprobado | G4: Ciclo 2 | H4: 46323 | I4: Luzzi | J4: Aprobado | K4: A mitad del corredor de la fila 7 (posición 3.33, sin intersección), ← invirtió la marcha de inmediato: dirección «left», posición 3.33 → 1.92. (Fantasmas retirados y posiciones preparadas por script para aislar la condición.)
A5: Prioridad (Alta, Media, Baja) | B5: Media | C5: Técnica de diseño | D5: Partición de equivalencia | G5: Ciclo 3
G6: Ciclo 1 = Entrega 1 (V1). Ciclo 2 = Entrega 2 (V2): ejecución con script de navegador; las precondiciones preparadas por script se aclaran en el resultado obtenido.
A7: # | B7: Pre-requisitos | D7: Datos de prueba
A8: 1 | B8: Abrir la aplicación en un navegador de escritorio. | D8: Entorno: | E8: Build del commit 7ec70df (V2)
A9: 2 | B9: Elegir «Modo PacMan» en el menú principal y presionar Enter (HU-22). | D9: Navegador: | E9: Chromium 141 de escritorio
A10: 3 | B10: Partida en curso (N1), Pacman avanzando hacia la derecha en un corredor. | D10: Modo de juego: | E10: Pacman
A12: Título del CP | B12: Inversión de marcha a mitad de corredor
A15: Historias de Usuario | B15: HU-01 | C15: Épica | D15: E1 — Núcleo de juego y movimiento
A16: Estado Automatización | B16: Automatizado (script de navegador, Entrega 2) | C16: Camino feliz | D16: No
A18: Pasos # | B18: Detalle de pasos | D18: Resultado esperado
A19: 1 | B19: Presionar ← a mitad del corredor. | D19: Pacman invierte su marcha de inmediato, sin necesidad de llegar a una intersección.
A20: El caso se aprueba solo si se cumple todo el resultado esperado del último paso (en negrita); si cualquier parte no se cumple, se registra como Fallido.

Sheet CP-007
A1: Test Case ID | B1: CP-007 | C1: Descripción / Funcionalidad | D1: HU-02 · Impedir el paso a través de los muros | G1: Registro de ejecución
A2: Creado por | B2: Cruz, Luzzi (mutación: Luzzi) | C2: Versión | D2: 2 | G2: Ciclo | H2: Fecha | I2: Ejecutor | J2: Estado | K2: Resultado obtenido | L2: Defecto
A3: Reporte de ejecución 2 | C3: Estado en la Entrega 2 | D3: =IFERROR(IF(INDEX('Reporte de ejecución - Entrega2'!$I$4:$I$132,MATCH($B$1,'Reporte de ejecución - Entrega2'!$A$4:$A$132,0))="","Sin ejecutar",INDEX('Reporte de ejecución - Entrega2'!$I$4:$I$132,MATCH($B$1,'Reporte de ejecución - Entrega2'!$A$4:$A$132,0))),"Sin ejecutar") | G3: Ciclo 1 | H3: 46294 | I3: Rodriguez Castro | J3: Aprobado | K3: Aprobado. La tecla sostenida se simuló con pulsaciones repetidas (39 en 5 s). Durante la prueba los fantasmas alcanzaron dos veces a Pacman, que reapareció en la misma celda junto al muro; la verificación continuó sin cambios.
C4: Estado en la Entrega 1 | D4: Aprobado | G4: Ciclo 2 | H4: 46307 | I4: Luzzi | J4: Aprobado | K4: Con ← mantenida 5 s contra el muro izquierdo, Pacman se detuvo en (7,1) sin superponerse; luego ↑ lo movió con normalidad (fila 5). (Fantasmas retirados y posiciones preparadas por script para aislar la condición.)
A5: Prioridad (Alta, Media, Baja) | B5: Alta | C5: Técnica de diseño | D5: Valores límite | G5: Ciclo 3
G6: Ciclo 1 = Entrega 1 (V1). Ciclo 2 = Entrega 2 (V2): ejecución con script de navegador; las precondiciones preparadas por script se aclaran en el resultado obtenido.
A7: # | B7: Pre-requisitos | D7: Datos de prueba
A8: 1 | B8: Abrir la aplicación en un navegador de escritorio. | D8: Entorno: | E8: Build del commit 7ec70df (V2)
A9: 2 | B9: Elegir «Modo PacMan» en el menú principal y presionar Enter (HU-22). | D9: Navegador: | E9: Chromium 141 de escritorio
A10: 3 | B10: Partida en curso (N1). | D10: Modo de juego: | E10: Pacman
A12: Título del CP | B12: Pacman no atraviesa los muros
A15: Historias de Usuario | B15: HU-02 | C15: Épica | D15: E1 — Núcleo de juego y movimiento
A16: Estado Automatización | B16: Automatizado (script de navegador, Entrega 2) | C16: Camino feliz | D16: No
A18: Mutación (Entrega 2) | B18: Contra un muro a la izquierda (en la V1, a la derecha).
A20: Pasos # | B20: Detalle de pasos | D20: Resultado esperado
A21: 1 | B21: Dirigir a Pacman contra un muro. | D21: Pacman avanza hasta quedar junto al muro.
A22: 2 | B22: Mantener presionada la tecla de esa dirección durante 5 segundos. | D22: Pacman se detiene contra el muro, no lo atraviesa, no queda superpuesto al muro y no queda encajado: al indicar otra dirección válida se mueve con normalidad.
A23: El caso se aprueba solo si se cumple todo el resultado esperado del último paso (en negrita); si cualquier parte no se cumple, se registra como Fallido.

Sheet CP-008
A1: Test Case ID | B1: CP-008 | C1: Descripción / Funcionalidad | D1: HU-02 · Impedir el paso a través de los muros | G1: Registro de ejecución
A2: Creado por | B2: Cruz, Luzzi (mutación: Luzzi) | C2: Versión | D2: 2 | G2: Ciclo | H2: Fecha | I2: Ejecutor | J2: Estado | K2: Resultado obtenido | L2: Defecto
A3: Reporte de ejecución 2 | C3: Estado en la Entrega 2 | D3: =IFERROR(IF(INDEX('Reporte de ejecución - Entrega2'!$I$4:$I$132,MATCH($B$1,'Reporte de ejecución - Entrega2'!$A$4:$A$132,0))="","Sin ejecutar",INDEX('Reporte de ejecución - Entrega2'!$I$4:$I$132,MATCH($B$1,'Reporte de ejecución - Entrega2'!$A$4:$A$132,0))),"Sin ejecutar") | G3: Ciclo 1 | H3: 46294 | I3: Rodriguez Castro | J3: Aprobado | K3: Aprobado. Se usaron las esquinas porque las rutas por las columnas centrales son interceptadas por los fantasmas. Al llegar a las esquinas Pacman comió la esfera grande y se activó el PowerUp; no afecta la verificación de límites.
C4: Estado en la Entrega 1 | D4: Aprobado | G4: Ciclo 2 | H4: 46307 | I4: Luzzi | J4: Aprobado | K4: En los bordes abajo (13,8), derecha (7,15), arriba (1,8) e izquierda (7,1), con la tecla hacia afuera, Pacman no salió del mapa y quedó visible. (Fantasmas retirados y posiciones preparadas por script para aislar la condición.)
A5: Prioridad (Alta, Media, Baja) | B5: Alta | C5: Técnica de diseño | D5: Valores límite | G5: Ciclo 3
G6: Ciclo 1 = Entrega 1 (V1). Ciclo 2 = Entrega 2 (V2): ejecución con script de navegador; las precondiciones preparadas por script se aclaran en el resultado obtenido.
A7: # | B7: Pre-requisitos | D7: Datos de prueba
A8: 1 | B8: Abrir la aplicación en un navegador de escritorio. | D8: Entorno: | E8: Build del commit 7ec70df (V2)
A9: 2 | B9: Elegir «Modo PacMan» en el menú principal y presionar Enter (HU-22). | D9: Navegador: | E9: Chromium 141 de escritorio
A10: 3 | B10: Partida en curso (N1). | D10: Modo de juego: | E10: Pacman
A12: Título del CP | B12: Pacman no sale de los límites del mapa
A15: Historias de Usuario | B15: HU-02 | C15: Épica | D15: E1 — Núcleo de juego y movimiento
A16: Estado Automatización | B16: Automatizado (script de navegador, Entrega 2) | C16: Camino feliz | D16: No
A18: Mutación (Entrega 2) | B18: Bordes recorridos en otro orden: abajo, derecha, arriba, izquierda.
A20: Pasos # | B20: Detalle de pasos | D20: Resultado esperado
A21: 1 | B21: Llevar a Pacman al borde del mapa por cada uno de los cuatro lados. | D21: Pacman llega al borde del mapa en cada lado.
A22: 2 | B22: Presionar la tecla que apunta hacia afuera del mapa. | D22: Pacman no sale del mapa por ninguno de los cuatro lados y permanece visible en pantalla.
A23: El caso se aprueba solo si se cumple todo el resultado esperado del último paso (en negrita); si cualquier parte no se cumple, se registra como Fallido.

Sheet CP-009
A1: Test Case ID | B1: CP-009 | C1: Descripción / Funcionalidad | D1: HU-02 · Impedir el paso a través de los muros | G1: Registro de ejecución
A2: Creado por | B2: Cruz, Luzzi (mutación: Luzzi) | C2: Versión | D2: 2 | G2: Ciclo | H2: Fecha | I2: Ejecutor | J2: Estado | K2: Resultado obtenido | L2: Defecto
A3: Reporte de ejecución 2 | C3: Estado en la Entrega 2 | D3: =IFERROR(IF(INDEX('Reporte de ejecución - Entrega2'!$I$4:$I$132,MATCH($B$1,'Reporte de ejecución - Entrega2'!$A$4:$A$132,0))="","Sin ejecutar",INDEX('Reporte de ejecución - Entrega2'!$I$4:$I$132,MATCH($B$1,'Reporte de ejecución - Entrega2'!$A$4:$A$132,0))),"Sin ejecutar") | G3: Ciclo 1 | H3: 46294 | I3: Rodriguez Castro | J3: Aprobado | K3: Aprobado. Pacman quieto: murió 24 veces y la partida se reinició 8 veces para mantener a los fantasmas en movimiento los 60 s. Los fantasmas recorrieron 13 celdas cada uno.
C4: Estado en la Entrega 1 | D4: Aprobado | G4: Ciclo 2 | H4: 46307 | I4: Luzzi | J4: Aprobado | K4: Nivel 2 durante 60 s: ningún fantasma clásico entró a un muro ni salió del mapa (tipos observados: ['classic']). (Vidas repuestas por script para que la partida no termine.)
A5: Prioridad (Alta, Media, Baja) | B5: Alta | C5: Técnica de diseño | D5: Adivinación de errores | G5: Ciclo 3
G6: Ciclo 1 = Entrega 1 (V1). Ciclo 2 = Entrega 2 (V2): ejecución con script de navegador; las precondiciones preparadas por script se aclaran en el resultado obtenido.
A7: # | B7: Pre-requisitos | D7: Datos de prueba
A8: 1 | B8: Abrir la aplicación en un navegador de escritorio. | D8: Entorno: | E8: Build del commit 7ec70df (V2)
A9: 2 | B9: Elegir «Modo PacMan» en el menú principal y presionar Enter (HU-22). | D9: Navegador: | E9: Chromium 141 de escritorio
A10: 3 | B10: Partida en curso (N1). | D10: Modo de juego: | E10: Pacman
A12: Título del CP | B12: Los fantasmas clásicos no atraviesan muros
A15: Historias de Usuario | B15: HU-02 | C15: Épica | D15: E1 — Núcleo de juego y movimiento
A16: Estado Automatización | B16: Automatizado (script de navegador, Entrega 2) | C16: Camino feliz | D16: No
A18: Mutación (Entrega 2) | B18: Observación en el nivel 2 en lugar del 1 (solo clásicos al inicio), 60 s.
A20: Pasos # | B20: Detalle de pasos | D20: Resultado esperado
A21: 1 | B21: Observar el desplazamiento de los cuatro fantasmas durante 60 segundos. | D21: Ningún fantasma atraviesa un muro ni sale de los límites del mapa en ningún momento.
A22: El caso se aprueba solo si se cumple todo el resultado esperado del último paso (en negrita); si cualquier parte no se cumple, se registra como Fallido.

Sheet CP-010
A1: Test Case ID | B1: CP-010 | C1: Descripción / Funcionalidad | D1: HU-02 · Impedir el paso a través de los muros | G1: Registro de ejecución
A2: Creado por | B2: Cruz, Luzzi | C2: Versión | D2: 1 | G2: Ciclo | H2: Fecha | I2: Ejecutor | J2: Estado | K2: Resultado obtenido | L2: Defecto
A3: Reporte de ejecución 2 | C3: Estado en la Entrega 2 | D3: =IFERROR(IF(INDEX('Reporte de ejecución - Entrega2'!$I$4:$I$132,MATCH($B$1,'Reporte de ejecución - Entrega2'!$A$4:$A$132,0))="","Sin ejecutar",INDEX('Reporte de ejecución - Entrega2'!$I$4:$I$132,MATCH($B$1,'Reporte de ejecución - Entrega2'!$A$4:$A$132,0))),"Sin ejecutar") | G3: Ciclo 1 | H3: 46294 | I3: Rodriguez Castro | J3: Aprobado | K3: Aprobado. Recorrido parcial con Pacman, complementado con la comparación completa entre dibujo y lógica. Los 107 caminos coinciden con lo dibujado. Única celda transitable sin punto: la de inicio de Pacman (7,8); se asume por diseño, a confirmar con el equipo.
C4: Estado en la Entrega 1 | D4: Aprobado | G4: Ciclo 2 | H4: 46323 | I4: Luzzi | J4: Aprobado | K4: Nivel 1: 107 celdas transitables, todas alcanzables desde la posición de Pacman; 106 marcadas con esfera y la única sin marca es la celda inicial de Pacman (7,8), que ocupa él mismo. Ningún muro tiene esfera. (Recorrido verificado sobre el mapa del juego.)
A5: Prioridad (Alta, Media, Baja) | B5: Media | C5: Técnica de diseño | D5: Adivinación de errores | G5: Ciclo 3
G6: Ciclo 1 = Entrega 1 (V1). Ciclo 2 = Entrega 2 (V2): ejecución con script de navegador; las precondiciones preparadas por script se aclaran en el resultado obtenido.
A7: # | B7: Pre-requisitos | D7: Datos de prueba
A8: 1 | B8: Abrir la aplicación en un navegador de escritorio. | D8: Entorno: | E8: Build del commit 7ec70df (V2)
A9: 2 | B9: Elegir «Modo PacMan» en el menú principal y presionar Enter (HU-22). | D9: Navegador: | E9: Chromium 141 de escritorio
A10: 3 | B10: Partida en curso (N1). | D10: Modo de juego: | E10: Pacman
A12: Título del CP | B12: Zona transitable coincidente con el mapa dibujado
A15: Historias de Usuario | B15: HU-02 | C15: Épica | D15: E1 — Núcleo de juego y movimiento
A16: Estado Automatización | B16: Automatizado (script de navegador, Entrega 2) | C16: Camino feliz | D16: No
A18: Pasos # | B18: Detalle de pasos | D18: Resultado esperado
A19: 1 | B19: Recorrer con Pacman los caminos marcados con puntos blancos. | D19: Todos los caminos marcados son transitables, y no existe ninguna celda transitable que no esté marcada como camino.
A20: El caso se aprueba solo si se cumple todo el resultado esperado del último paso (en negrita); si cualquier parte no se cumple, se registra como Fallido.

Sheet CP-011
A1: Test Case ID | B1: CP-011 | C1: Descripción / Funcionalidad | D1: HU-03 · Consumir las esferas del mapa | G1: Registro de ejecución
A2: Creado por | B2: Cruz, Luzzi (mutación: Luzzi) | C2: Versión | D2: 2 | G2: Ciclo | H2: Fecha | I2: Ejecutor | J2: Estado | K2: Resultado obtenido | L2: Defecto
A3: Reporte de ejecución 2 | C3: Estado en la Entrega 2 | D3: =IFERROR(IF(INDEX('Reporte de ejecución - Entrega2'!$I$4:$I$132,MATCH($B$1,'Reporte de ejecución - Entrega2'!$A$4:$A$132,0))="","Sin ejecutar",INDEX('Reporte de ejecución - Entrega2'!$I$4:$I$132,MATCH($B$1,'Reporte de ejecución - Entrega2'!$A$4:$A$132,0))),"Sin ejecutar") | G3: Ciclo 1 | H3: 46294 | I3: Rodriguez Castro | J3: Aprobado | K3: Aprobado.
C4: Estado en la Entrega 1 | D4: Aprobado | G4: Ciclo 2 | H4: 46307 | I4: Luzzi | J4: Aprobado | K4: Esfera de (4,3): desapareció; puntaje 0 → 10 (+10); esferas restantes 105 → 104. (Fantasmas retirados y posiciones preparadas por script para aislar la condición.)
A5: Prioridad (Alta, Media, Baja) | B5: Alta | C5: Técnica de diseño | D5: Partición de equivalencia | G5: Ciclo 3
G6: Ciclo 1 = Entrega 1 (V1). Ciclo 2 = Entrega 2 (V2): ejecución con script de navegador; las precondiciones preparadas por script se aclaran en el resultado obtenido.
A7: # | B7: Pre-requisitos | D7: Datos de prueba
A8: 1 | B8: Abrir la aplicación en un navegador de escritorio. | D8: Entorno: | E8: Build del commit 7ec70df (V2)
A9: 2 | B9: Elegir «Modo PacMan» en el menú principal y presionar Enter (HU-22). | D9: Navegador: | E9: Chromium 141 de escritorio
A10: 3 | B10: Partida en curso (N1), puntaje 0. | D10: Modo de juego: | E10: Pacman
A12: Título del CP | B12: Consumo de una esfera común
A15: Historias de Usuario | B15: HU-03 | C15: Épica | D15: E1 — Núcleo de juego y movimiento
A16: Estado Automatización | B16: Automatizado (script de navegador, Entrega 2) | C16: Camino feliz | D16: Sí
A18: Mutación (Entrega 2) | B18: Esfera común de otra fila (fila 4).
A20: Pasos # | B20: Detalle de pasos | D20: Resultado esperado
A21: 1 | B21: Registrar el puntaje y el contador de esferas restantes. | D21: Puntaje y contador de esferas anotados como valores de referencia.
A22: 2 | B22: Desplazar a Pacman sobre una esfera común. | D22: Pacman pasa por la celda de la esfera.
A23: 3 | B23: Registrar ambos valores. | D23: La esfera desaparece del mapa, el puntaje aumenta exactamente 10 y el contador de esferas restantes disminuye exactamente 1.
A24: El caso se aprueba solo si se cumple todo el resultado esperado del último paso (en negrita); si cualquier parte no se cumple, se registra como Fallido.

Sheet CP-012
A1: Test Case ID | B1: CP-012 | C1: Descripción / Funcionalidad | D1: HU-03 · Consumir las esferas del mapa | G1: Registro de ejecución
A2: Creado por | B2: Cruz, Luzzi (mutación: Luzzi) | C2: Versión | D2: 2 | G2: Ciclo | H2: Fecha | I2: Ejecutor | J2: Estado | K2: Resultado obtenido | L2: Defecto
A3: Reporte de ejecución 2 | C3: Estado en la Entrega 2 | D3: =IFERROR(IF(INDEX('Reporte de ejecución - Entrega2'!$I$4:$I$132,MATCH($B$1,'Reporte de ejecución - Entrega2'!$A$4:$A$132,0))="","Sin ejecutar",INDEX('Reporte de ejecución - Entrega2'!$I$4:$I$132,MATCH($B$1,'Reporte de ejecución - Entrega2'!$A$4:$A$132,0))),"Sin ejecutar") | G3: Ciclo 1 | H3: 46294 | I3: Rodriguez Castro | J3: Aprobado | K3: Aprobado. En la corrida Pacman comió también la esfera grande de (1,1), por lo que la vida se perdió más tarde de lo previsto. La verificación posterior a la pérdida de vidas no se ve afectada.
C4: Estado en la Entrega 1 | D4: Aprobado | G4: Ciclo 2 | H4: 46307 | I4: Luzzi | J4: Aprobado | K4: Pacman consumió 14 esferas en la fila 10; tras perder una vida (3 → 2) la fila sigue despejada (15 de 15 celdas sin esfera). (Fantasmas retirados y posiciones preparadas por script para aislar la condición.)
A5: Prioridad (Alta, Media, Baja) | B5: Alta | C5: Técnica de diseño | D5: Adivinación de errores | G5: Ciclo 3
G6: Ciclo 1 = Entrega 1 (V1). Ciclo 2 = Entrega 2 (V2): ejecución con script de navegador; las precondiciones preparadas por script se aclaran en el resultado obtenido.
A7: # | B7: Pre-requisitos | D7: Datos de prueba
A8: 1 | B8: Abrir la aplicación en un navegador de escritorio. | D8: Entorno: | E8: Build del commit 7ec70df (V2)
A9: 2 | B9: Elegir «Modo PacMan» en el menú principal y presionar Enter (HU-22). | D9: Navegador: | E9: Chromium 141 de escritorio
A10: 3 | B10: Partida en curso (N1). | D10: Modo de juego: | E10: Pacman
